<sdf version='1.7'>
  <world name='default'>
    <model name='ground_plane'>
      <static>1</static>
      <link name='link'>
        <collision name='collision'>
          <geometry>
            <plane>
              <normal>0 0 1</normal>
              <size>100 100</size>
            </plane>
          </geometry>
          <surface>
            <contact>
              <collide_bitmask>65535</collide_bitmask>
              <ode/>
            </contact>
            <friction>
              <ode>
                <mu>100</mu>
                <mu2>50</mu2>
              </ode>
              <torsional>
                <ode/>
              </torsional>
            </friction>
            <bounce/>
          </surface>
          <max_contacts>10</max_contacts>
        </collision>
        <visual name='visual'>
          <cast_shadows>0</cast_shadows>
          <geometry>
            <plane>
              <normal>0 0 1</normal>
              <size>100 100</size>
            </plane>
          </geometry>
          <material>
            <script>
              <uri>file://media/materials/scripts/gazebo.material</uri>
              <name>Gazebo/Grey</name>
            </script>
          </material>
        </visual>
        <self_collide>0</self_collide>
        <enable_wind>0</enable_wind>
        <kinematic>0</kinematic>
      </link>
    </model>
    <light name='sun' type='directional'>
      <cast_shadows>1</cast_shadows>
      <pose>0 0 10 0 -0 0</pose>
      <diffuse>0.8 0.8 0.8 1</diffuse>
      <specular>0.2 0.2 0.2 1</specular>
      <attenuation>
        <range>1000</range>
        <constant>0.9</constant>
        <linear>0.01</linear>
        <quadratic>0.001</quadratic>
      </attenuation>
      <direction>-0.5 0.1 -0.9</direction>
      <spot>
        <inner_angle>0</inner_angle>
        <outer_angle>0</outer_angle>
        <falloff>0</falloff>
      </spot>
    </light>
    <physics type='ode'>
      <real_time_update_rate>1000</real_time_update_rate>
      <max_step_size>0.001</max_step_size>
      <real_time_factor>1</real_time_factor>
    </physics>
    <gravity>0 0 -9.81</gravity>
    <gui fullscreen='0'>
      <camera name='user_camera'>
        <pose>5.80839 -4.74913 3.63285 0 0.399643 2.75619</pose>
        <view_controller>orbit</view_controller>
        <projection_type>perspective</projection_type>
      </camera>
    </gui>
    <magnetic_field>6e-06 2.3e-05 -4.2e-05</magnetic_field>
    <atmosphere type='adiabatic'/>
    <scene>
      <ambient>0.4 0.4 0.4 1</ambient>
      <background>0.7 0.7 0.7 1</background>
      <shadows>1</shadows>
    </scene>
    <wind/>
    <spherical_coordinates>
      <surface_model>EARTH_WGS84</surface_model>
      <latitude_deg>0</latitude_deg>
      <longitude_deg>0</longitude_deg>
      <elevation>0</elevation>
      <heading_deg>0</heading_deg>
    </spherical_coordinates>
    <model name='baxter'>
      <joint name='fixed' type='fixed'>
        <pose relative_to='__model__'>0 0 0 0 -0 0</pose>
        <parent>world</parent>
        <child>base</child>
      </joint>
      <link name='base'>
        <pose relative_to='fixed'>0 0 0 0 -0 0</pose>
        <inertial>
          <pose>0 -0 3e-06 0 -0 0</pose>
          <mass>96.2011</mass>
          <inertia>
            <ixx>6.91297</ixx>
            <ixy>0.00068017</ixy>
            <ixz>0.64779</ixz>
            <iyy>7.74978</iyy>
            <iyz>0.00434511</iyz>
            <izz>5.76418</izz>
          </inertia>
        </inertial>
        <collision name='base_fixed_joint_lump__collision_head_link_1_collision'>
          <pose>0.04 -0.04 0.75 0 -0 0</pose>
          <geometry>
            <sphere>
              <radius>0.22</radius>
            </sphere>
          </geometry>
          <surface>
            <contact>
              <ode/>
            </contact>
            <bounce/>
            <friction>
              <torsional>
                <ode/>
              </torsional>
              <ode/>
            </friction>
          </surface>
          <max_contacts>10</max_contacts>
        </collision>
        <collision name='base_fixed_joint_lump__collision_head_link_2_collision_1'>
          <pose>0.04 0.04 0.75 0 -0 0</pose>
          <geometry>
            <sphere>
              <radius>0.22</radius>
            </sphere>
          </geometry>
          <surface>
            <contact>
              <ode/>
            </contact>
            <bounce/>
            <friction>
              <torsional>
                <ode/>
              </torsional>
              <ode/>
            </friction>
          </surface>
          <max_contacts>10</max_contacts>
        </collision>
        <collision name='base_fixed_joint_lump__torso_collision_2'>
          <pose>0 0 0 0 -0 0</pose>
          <geometry>
            <mesh>
              <scale>1 1 1</scale>
              <uri>/home/gabbiewink/rethink_ws/src/baxter_common/baxter_description/meshes/torso/base_link_collision.DAE</uri>
            </mesh>
          </geometry>
          <surface>
            <contact>
              <ode/>
            </contact>
            <friction>
              <ode/>
              <torsional>
                <ode/>
              </torsional>
            </friction>
            <bounce/>
          </surface>
          <max_contacts>10</max_contacts>
        </collision>
        <collision name='base_fixed_joint_lump__pedestal_collision_3'>
          <pose>0 0 0 0 -0 0</pose>
          <geometry>
            <mesh>
              <scale>1 1 1</scale>
              <uri>/home/gabbiewink/rethink_ws/src/baxter_common/baxter_description/meshes/base/pedestal_link_collision.DAE</uri>
            </mesh>
          </geometry>
          <surface>
            <contact>
              <ode/>
            </contact>
            <bounce/>
            <friction>
              <torsional>
                <ode/>
              </torsional>
              <ode/>
            </friction>
          </surface>
          <max_contacts>10</max_contacts>
        </collision>
        <collision name='base_fixed_joint_lump__sonar_ring_collision_4'>
          <pose>0.0947 0 0.817 0 -0 0</pose>
          <geometry>
            <sphere>
              <radius>0.001</radius>
            </sphere>
          </geometry>
          <surface>
            <contact>
              <ode/>
            </contact>
            <friction>
              <ode/>
              <torsional>
                <ode/>
              </torsional>
            </friction>
            <bounce/>
          </surface>
          <max_contacts>10</max_contacts>
        </collision>
        <visual name='base_fixed_joint_lump__collision_head_link_1_visual'>
          <pose>0.11 0 0.75 0 -0 0</pose>
          <geometry>
            <sphere>
              <radius>0.001</radius>
            </sphere>
          </geometry>
        </visual>
        <visual name='base_fixed_joint_lump__collision_head_link_2_visual_1'>
          <pose>0.11 0 0.75 0 -0 0</pose>
          <geometry>
            <sphere>
              <radius>0.001</radius>
            </sphere>
          </geometry>
        </visual>
        <visual name='base_fixed_joint_lump__torso_visual_2'>
          <pose>0 0 0 0 -0 0</pose>
          <geometry>
            <mesh>
              <scale>1 1 1</scale>
              <uri>/home/gabbiewink/rethink_ws/src/baxter_common/baxter_description/meshes/torso/base_link.DAE</uri>
            </mesh>
          </geometry>
        </visual>
        <visual name='base_fixed_joint_lump__pedestal_visual_3'>
          <pose>0 0 0 0 -0 0</pose>
          <geometry>
            <mesh>
              <scale>1 1 1</scale>
              <uri>/home/gabbiewink/rethink_ws/src/baxter_common/baxter_description/meshes/base/PEDESTAL.DAE</uri>
            </mesh>
          </geometry>
        </visual>
        <visual name='base_fixed_joint_lump__sonar_ring_visual_4'>
          <pose>0.06 0 0.82653 0 -0 0</pose>
          <geometry>
            <cylinder>
              <length>0.01</length>
              <radius>0.085</radius>
            </cylinder>
          </geometry>
        </visual>
        <velocity_decay/>
        <self_collide>1</self_collide>
        <gravity>1</gravity>
        <velocity_decay/>
        <sensor name='sonar' type='ray'>
          <ray>
            <scan>
              <horizontal>
                <samples>12</samples>
                <resolution>1</resolution>
                <min_angle>-3.14</min_angle>
                <max_angle>3.14</max_angle>
              </horizontal>
              <vertical>
                <samples>2</samples>
                <resolution>1</resolution>
                <min_angle>-0.001</min_angle>
                <max_angle>0</max_angle>
              </vertical>
            </scan>
            <range>
              <min>0.05</min>
              <max>50</max>
            </range>
          </ray>
          <plugin name='sonar_plugin' filename='libgazebo_ros_block_laser.so'>
            <gaussianNoise>0.00</gaussianNoise>
            <alwaysOn>1</alwaysOn>
            <updateRate>100.0</updateRate>
            <topicName>/robot/sonar/head_sonar/state</topicName>
            <frameName>sonar_ring</frameName>
            <robotNamespace>/</robotNamespace>
          </plugin>
          <always_on>1</always_on>
          <update_rate>100</update_rate>
          <pose>0.0947 0 0.817 0 -0 0</pose>
        </sensor>
        <enable_wind>0</enable_wind>
        <kinematic>0</kinematic>
      </link>
      <joint name='head_pan' type='revolute'>
        <pose relative_to='base'>0.06 0 0.686 0 -0 0</pose>
        <parent>base</parent>
        <child>head</child>
        <axis>
          <xyz>0 0 1</xyz>
          <limit>
            <lower>-1.3963</lower>
            <upper>1.3963</upper>
            <effort>50000</effort>
            <velocity>10000</velocity>
          </limit>
          <dynamics>
            <damping>0.7</damping>
            <friction>0</friction>
            <spring_reference>0</spring_reference>
            <spring_stiffness>0</spring_stiffness>
          </dynamics>
        </axis>
        <physics>
          <ode>
            <implicit_spring_damper>1</implicit_spring_damper>
            <cfm_damping>1</cfm_damping>
            <limit>
              <cfm>0</cfm>
              <erp>0.2</erp>
            </limit>
          </ode>
        </physics>
      </joint>
      <link name='head'>
        <pose relative_to='head_pan'>0 0 0 0 -0 0</pose>
        <inertial>
          <pose>0.054677 0 5e-06 0 -0 0</pose>
          <mass>0.988238</mass>
          <inertia>
            <ixx>0.00620194</ixx>
            <ixy>0.000202093</ixy>
            <ixz>0.000495898</ixz>
            <iyy>0.010977</iyy>
            <iyz>-0.00109806</iyz>
            <izz>0.00983914</izz>
          </inertia>
        </inertial>
        <collision name='head_collision'>
          <pose>0 0 0 0 -0 0</pose>
          <geometry>
            <sphere>
              <radius>0.001</radius>
            </sphere>
          </geometry>
          <surface>
            <contact>
              <ode/>
            </contact>
            <bounce/>
            <friction>
              <torsional>
                <ode/>
              </torsional>
              <ode/>
            </friction>
          </surface>
          <max_contacts>10</max_contacts>
        </collision>
        <collision name='head_fixed_joint_lump__screen_collision_1'>
          <pose>0.1227 0 0 1.75057 0 1.5708</pose>
          <geometry>
            <sphere>
              <radius>0.001</radius>
            </sphere>
          </geometry>
          <surface>
            <contact>
              <ode/>
            </contact>
            <bounce/>
            <friction>
              <torsional>
                <ode/>
              </torsional>
              <ode/>
            </friction>
          </surface>
          <max_contacts>10</max_contacts>
        </collision>
        <visual name='head_visual'>
          <pose>0 0 0.00953 0 -0 0</pose>
          <geometry>
            <mesh>
              <scale>1 1 1</scale>
              <uri>/home/gabbiewink/rethink_ws/src/baxter_common/baxter_description/meshes/head/H0.DAE</uri>
            </mesh>
          </geometry>
        </visual>
        <visual name='head_fixed_joint_lump__screen_visual_1'>
          <pose>0.086855 0 -0.003172 1.5708 0.179774 0</pose>
          <geometry>
            <mesh>
              <scale>1 1 1</scale>
              <uri>/home/gabbiewink/rethink_ws/src/baxter_common/baxter_description/meshes/head/H1.DAE</uri>
            </mesh>
          </geometry>
        </visual>
        <visual name='head_fixed_joint_lump__display_visual_2'>
          <pose>0.119839 0 -0.015742 2.01237 0 1.5708</pose>
          <geometry>
            <box>
              <size>0.218 0.16 0.001</size>
            </box>
          </geometry>
          <plugin name='screen_video_controller' filename='libgazebo_ros_video.so'>
            <height>600</height>
            <width>1024</width>
            <topicName>/robot/xdisplay</topicName>
            <robotNamespace>/</robotNamespace>
          </plugin>
        </visual>
        <velocity_decay/>
        <sensor name='head_camera' type='camera'>
          <update_rate>30</update_rate>
          <camera name='head_camera'>
            <pose>0 0.21 0 -0 -0.8 -1.5708</pose>
            <horizontal_fov>1.39626</horizontal_fov>
            <image>
              <width>800</width>
              <height>800</height>
              <format>R8G8B8</format>
            </image>
            <clip>
              <near>0.02</near>
              <far>300</far>
            </clip>
            <noise>
              <type>gaussian</type>
              <mean>0</mean>
              <stddev>0.007</stddev>
            </noise>
          </camera>
          <plugin name='camera_controller' filename='libgazebo_ros_camera.so'>
            <alwaysOn>1</alwaysOn>
            <updateRate>0.0</updateRate>
            <cameraName>head_camera</cameraName>
            <imageTopicName>image</imageTopicName>
            <cameraInfoTopicName>camera_info</cameraInfoTopicName>
            <frameName>head_camera</frameName>
            <hackBaseline>0.07</hackBaseline>
            <distortionK1>0.0</distortionK1>
            <distortionK2>0.0</distortionK2>
            <distortionK3>0.0</distortionK3>
            <distortionT1>0.0</distortionT1>
            <distortionT2>0.0</distortionT2>
            <robotNamespace>/cameras</robotNamespace>
          </plugin>
          <pose>0.12839 0 0.06368 1.75057 0 1.5708</pose>
        </sensor>
        <gravity>1</gravity>
        <velocity_decay/>
        <self_collide>0</self_collide>
        <enable_wind>0</enable_wind>
        <kinematic>0</kinematic>
      </link>
      <joint name='left_s0' type='revolute'>
        <pose relative_to='base'>0.064027 0.259027 0.129626 0 -0 0.7854</pose>
        <parent>base</parent>
        <child>left_upper_shoulder</child>
        <axis>
          <xyz>0 0 1</xyz>
          <limit>
            <lower>-1.70168</lower>
            <upper>1.70168</upper>
            <effort>50</effort>
            <velocity>1.5</velocity>
          </limit>
          <dynamics>
            <damping>0.7</damping>
            <friction>0</friction>
            <spring_reference>0</spring_reference>
            <spring_stiffness>0</spring_stiffness>
          </dynamics>
        </axis>
        <physics>
          <ode>
            <implicit_spring_damper>1</implicit_spring_damper>
            <cfm_damping>1</cfm_damping>
            <limit>
              <cfm>0</cfm>
              <erp>0.2</erp>
            </limit>
          </ode>
        </physics>
      </joint>
      <link name='left_upper_shoulder'>
        <pose relative_to='left_s0'>0 0 0 0 -0 0</pose>
        <inertial>
          <pose>0.01783 0.00086 0.19127 0 -0 0</pose>
          <mass>5.70044</mass>
          <inertia>
            <ixx>0.047091</ixx>
            <ixy>0.000127876</ixy>
            <ixz>0.0061487</ixz>
            <iyy>0.0376698</iyy>
            <iyz>0.000780869</iyz>
            <izz>0.0359599</izz>
          </inertia>
        </inertial>
        <collision name='left_upper_shoulder_collision'>
          <pose>0 0 0.1361 0 -0 0</pose>
          <geometry>
            <cylinder>
              <length>0.2722</length>
              <radius>0.06</radius>
            </cylinder>
          </geometry>
          <surface>
            <contact>
              <ode/>
            </contact>
            <bounce/>
            <friction>
              <torsional>
                <ode/>
              </torsional>
              <ode/>
            </friction>
          </surface>
          <max_contacts>10</max_contacts>
        </collision>
        <visual name='left_upper_shoulder_visual'>
          <pose>0 0 0 0 -0 0</pose>
          <geometry>
            <mesh>
              <scale>1 1 1</scale>
              <uri>/home/gabbiewink/rethink_ws/src/baxter_common/baxter_description/meshes/upper_shoulder/S0.DAE</uri>
            </mesh>
          </geometry>
        </visual>
        <self_collide>0</self_collide>
        <enable_wind>0</enable_wind>
        <kinematic>0</kinematic>
      </link>
      <joint name='left_s1' type='revolute'>
        <pose relative_to='left_upper_shoulder'>0.069 0 0.27035 -1.5708 0 0</pose>
        <parent>left_upper_shoulder</parent>
        <child>left_lower_shoulder</child>
        <axis>
          <xyz>0 0 1</xyz>
          <limit>
            <lower>-2.147</lower>
            <upper>1.047</upper>
            <effort>50</effort>
            <velocity>1.5</velocity>
          </limit>
          <dynamics>
            <damping>0.7</damping>
            <friction>0</friction>
            <spring_reference>0</spring_reference>
            <spring_stiffness>0</spring_stiffness>
          </dynamics>
        </axis>
        <physics>
          <ode>
            <implicit_spring_damper>1</implicit_spring_damper>
            <cfm_damping>1</cfm_damping>
            <limit>
              <cfm>0</cfm>
              <erp>0.2</erp>
            </limit>
          </ode>
        </physics>
      </joint>
      <link name='left_lower_shoulder'>
        <pose relative_to='left_s1'>0 0 0 0 -0 0</pose>
        <inertial>
          <pose>0.068451 0.00269 -0.00529 0 -0 0</pose>
          <mass>3.22708</mass>
          <inertia>
            <ixx>0.0117521</ixx>
            <ixy>-0.000300954</ixy>
            <ixz>0.00207674</ixz>
            <iyy>0.0278861</iyy>
            <iyz>-0.000188219</iyz>
            <izz>0.0207877</izz>
          </inertia>
        </inertial>
        <collision name='left_lower_shoulder_collision'>
          <pose>0 0 0 0 -0 0</pose>
          <geometry>
            <cylinder>
              <length>0.12</length>
              <radius>0.06</radius>
            </cylinder>
          </geometry>
          <surface>
            <contact>
              <ode/>
            </contact>
            <bounce/>
            <friction>
              <torsional>
                <ode/>
              </torsional>
              <ode/>
            </friction>
          </surface>
          <max_contacts>10</max_contacts>
        </collision>
        <collision name='left_lower_shoulder_fixed_joint_lump__left_upper_elbow_visual_collision_1'>
          <pose>0.2435 -0 0 1.5708 -0 1.5708</pose>
          <geometry>
            <cylinder>
              <length>0.273</length>
              <radius>0.06</radius>
            </cylinder>
          </geometry>
          <surface>
            <contact>
              <ode/>
            </contact>
            <bounce/>
            <friction>
              <torsional>
                <ode/>
              </torsional>
              <ode/>
            </friction>
          </surface>
          <max_contacts>10</max_contacts>
        </collision>
        <visual name='left_lower_shoulder_visual'>
          <pose>0 0 0 0 -0 0</pose>
          <geometry>
            <mesh>
              <scale>1 1 1</scale>
              <uri>/home/gabbiewink/rethink_ws/src/baxter_common/baxter_description/meshes/lower_shoulder/S1.DAE</uri>
            </mesh>
          </geometry>
        </visual>
        <self_collide>0</self_collide>
        <enable_wind>0</enable_wind>
        <kinematic>0</kinematic>
      </link>
      <joint name='left_e0' type='revolute'>
        <pose relative_to='left_lower_shoulder'>0.102 0 0 1.5708 -0 1.5708</pose>
        <parent>left_lower_shoulder</parent>
        <child>left_upper_elbow</child>
        <axis>
          <xyz>0 0 1</xyz>
          <limit>
            <lower>-3.05418</lower>
            <upper>3.05418</upper>
            <effort>50</effort>
            <velocity>1.5</velocity>
          </limit>
          <dynamics>
            <damping>0.7</damping>
            <friction>0</friction>
            <spring_reference>0</spring_reference>
            <spring_stiffness>0</spring_stiffness>
          </dynamics>
        </axis>
        <physics>
          <ode>
            <implicit_spring_damper>1</implicit_spring_damper>
            <cfm_damping>1</cfm_damping>
            <limit>
              <cfm>0</cfm>
              <erp>0.2</erp>
            </limit>
          </ode>
        </physics>
      </joint>
      <link name='left_upper_elbow'>
        <pose relative_to='left_e0'>0 0 0 0 -0 0</pose>
        <inertial>
          <pose>-0.00276 0.00132 0.18086 0 -0 0</pose>
          <mass>4.31272</mass>
          <inertia>
            <ixx>0.0266173</ixx>
            <ixy>0.000292706</ixy>
            <ixz>0.0039219</ixz>
            <iyy>0.0284436</iyy>
            <iyz>0.00108389</iyz>
            <izz>0.0124801</izz>
          </inertia>
        </inertial>
        <collision name='left_upper_elbow_collision'>
          <pose>0 0 -0.0535 0 -0 0</pose>
          <geometry>
            <cylinder>
              <length>0.107</length>
              <radius>0.06</radius>
            </cylinder>
          </geometry>
          <surface>
            <contact>
              <ode/>
            </contact>
            <bounce/>
            <friction>
              <torsional>
                <ode/>
              </torsional>
              <ode/>
            </friction>
          </surface>
          <max_contacts>10</max_contacts>
        </collision>
        <visual name='left_upper_elbow_visual'>
          <pose>0 0 0 0 -0 0</pose>
          <geometry>
            <mesh>
              <scale>1 1 1</scale>
              <uri>/home/gabbiewink/rethink_ws/src/baxter_common/baxter_description/meshes/upper_elbow/E0.DAE</uri>
            </mesh>
          </geometry>
        </visual>
        <self_collide>0</self_collide>
        <enable_wind>0</enable_wind>
        <kinematic>0</kinematic>
      </link>
      <joint name='left_e1' type='revolute'>
        <pose relative_to='left_upper_elbow'>0.069 0 0.26242 1.57079 -1.57079 3.14159</pose>
        <parent>left_upper_elbow</parent>
        <child>left_lower_elbow</child>
        <axis>
          <xyz>0 0 1</xyz>
          <limit>
            <lower>-0.05</lower>
            <upper>2.618</upper>
            <effort>50</effort>
            <velocity>1.5</velocity>
          </limit>
          <dynamics>
            <damping>0.7</damping>
            <friction>0</friction>
            <spring_reference>0</spring_reference>
            <spring_stiffness>0</spring_stiffness>
          </dynamics>
        </axis>
        <physics>
          <ode>
            <implicit_spring_damper>1</implicit_spring_damper>
            <cfm_damping>1</cfm_damping>
            <limit>
              <cfm>0</cfm>
              <erp>0.2</erp>
            </limit>
          </ode>
        </physics>
      </joint>
      <link name='left_lower_elbow'>
        <pose relative_to='left_e1'>0 0 0 0 -0 0</pose>
        <inertial>
          <pose>0.026113 0.00159 -0.011169 0 -0 0</pose>
          <mass>2.07216</mass>
          <inertia>
            <ixx>0.00711585</ixx>
            <ixy>0.000360372</ixy>
            <ixz>0.00074588</ixz>
            <iyy>0.0131827</iyy>
            <iyz>-0.000196632</iyz>
            <izz>0.00926891</izz>
          </inertia>
        </inertial>
        <collision name='left_lower_elbow_collision'>
          <pose>0 0 0 0 -0 0</pose>
          <geometry>
            <cylinder>
              <length>0.1</length>
              <radius>0.06</radius>
            </cylinder>
          </geometry>
          <surface>
            <contact>
              <ode/>
            </contact>
            <bounce/>
            <friction>
              <torsional>
                <ode/>
              </torsional>
              <ode/>
            </friction>
          </surface>
          <max_contacts>10</max_contacts>
        </collision>
        <collision name='left_lower_elbow_fixed_joint_lump__left_upper_forearm_visual_collision_1'>
          <pose>0.224 -0 0 1.5708 -0 1.5708</pose>
          <geometry>
            <cylinder>
              <length>0.272</length>
              <radius>0.06</radius>
            </cylinder>
          </geometry>
          <surface>
            <contact>
              <ode/>
            </contact>
            <bounce/>
            <friction>
              <torsional>
                <ode/>
              </torsional>
              <ode/>
            </friction>
          </surface>
          <max_contacts>10</max_contacts>
        </collision>
        <visual name='left_lower_elbow_visual'>
          <pose>0 0 0 0 -0 0</pose>
          <geometry>
            <mesh>
              <scale>1 1 1</scale>
              <uri>/home/gabbiewink/rethink_ws/src/baxter_common/baxter_description/meshes/lower_elbow/E1.DAE</uri>
            </mesh>
          </geometry>
        </visual>
        <self_collide>0</self_collide>
        <enable_wind>0</enable_wind>
        <kinematic>0</kinematic>
      </link>
      <joint name='left_w0' type='revolute'>
        <pose relative_to='left_lower_elbow'>0.10359 0 0 1.5708 -0 1.5708</pose>
        <parent>left_lower_elbow</parent>
        <child>left_upper_forearm</child>
        <axis>
          <xyz>0 0 1</xyz>
          <limit>
            <lower>-3.059</lower>
            <upper>3.059</upper>
            <effort>15</effort>
            <velocity>4</velocity>
          </limit>
          <dynamics>
            <damping>0.7</damping>
            <friction>0</friction>
            <spring_reference>0</spring_reference>
            <spring_stiffness>0</spring_stiffness>
          </dynamics>
        </axis>
        <physics>
          <ode>
            <implicit_spring_damper>1</implicit_spring_damper>
            <cfm_damping>1</cfm_damping>
            <limit>
              <cfm>0</cfm>
              <erp>0.2</erp>
            </limit>
          </ode>
        </physics>
      </joint>
      <link name='left_upper_forearm'>
        <pose relative_to='left_w0'>0 0 0 0 -0 0</pose>
        <inertial>
          <pose>-0.001682 0.0046 0.139519 0 -0 0</pose>
          <mass>2.24675</mass>
          <inertia>
            <ixx>0.0166775</ixx>
            <ixy>0.000184012</ixy>
            <ixz>0.000186469</ixz>
            <iyy>0.0167549</iyy>
            <iyz>-0.000647332</iyz>
            <izz>0.00374662</izz>
          </inertia>
        </inertial>
        <collision name='left_upper_forearm_collision'>
          <pose>0 0 -0.044 0 -0 0</pose>
          <geometry>
            <cylinder>
              <length>0.088</length>
              <radius>0.06</radius>
            </cylinder>
          </geometry>
          <surface>
            <contact>
              <ode/>
            </contact>
            <bounce/>
            <friction>
              <torsional>
                <ode/>
              </torsional>
              <ode/>
            </friction>
          </surface>
          <max_contacts>10</max_contacts>
        </collision>
        <visual name='left_upper_forearm_visual'>
          <pose>0 0 0 0 -0 0</pose>
          <geometry>
            <mesh>
              <scale>1 1 1</scale>
              <uri>/home/gabbiewink/rethink_ws/src/baxter_common/baxter_description/meshes/upper_forearm/W0.DAE</uri>
            </mesh>
          </geometry>
        </visual>
        <self_collide>0</self_collide>
        <enable_wind>0</enable_wind>
        <kinematic>0</kinematic>
      </link>
      <joint name='left_w1' type='revolute'>
        <pose relative_to='left_upper_forearm'>0.01 0 0.2707 1.57079 -1.57079 3.14159</pose>
        <parent>left_upper_forearm</parent>
        <child>left_lower_forearm</child>
        <axis>
          <xyz>0 0 1</xyz>
          <limit>
            <lower>-1.5708</lower>
            <upper>2.094</upper>
            <effort>15</effort>
            <velocity>4</velocity>
          </limit>
          <dynamics>
            <damping>0.7</damping>
            <friction>0</friction>
            <spring_reference>0</spring_reference>
            <spring_stiffness>0</spring_stiffness>
          </dynamics>
        </axis>
        <physics>
          <ode>
            <implicit_spring_damper>1</implicit_spring_damper>
            <cfm_damping>1</cfm_damping>
            <limit>
              <cfm>0</cfm>
              <erp>0.2</erp>
            </limit>
          </ode>
        </physics>
      </joint>
      <link name='left_lower_forearm'>
        <pose relative_to='left_w1'>0 0 0 0 -0 0</pose>
        <inertial>
          <pose>0.06041 0.00697 0.006 0 -0 0</pose>
          <mass>1.60979</mass>
          <inertia>
            <ixx>0.00387607</ixx>
            <ixy>-0.000443848</ixy>
            <ixz>-0.00021115</ixz>
            <iyy>0.00700538</iyy>
            <iyz>0.000153481</iyz>
            <izz>0.00552755</izz>
          </inertia>
        </inertial>
        <collision name='left_lower_forearm_collision'>
          <pose>0 0 0 0 -0 0</pose>
          <geometry>
            <cylinder>
              <length>0.1</length>
              <radius>0.06</radius>
            </cylinder>
          </geometry>
          <surface>
            <contact>
              <ode/>
            </contact>
            <bounce/>
            <friction>
              <torsional>
                <ode/>
              </torsional>
              <ode/>
            </friction>
          </surface>
          <max_contacts>10</max_contacts>
        </collision>
        <visual name='left_lower_forearm_visual'>
          <pose>0 0 0 0 -0 0</pose>
          <geometry>
            <mesh>
              <scale>1 1 1</scale>
              <uri>/home/gabbiewink/rethink_ws/src/baxter_common/baxter_description/meshes/lower_forearm/W1.DAE</uri>
            </mesh>
          </geometry>
        </visual>
        <self_collide>0</self_collide>
        <enable_wind>0</enable_wind>
        <kinematic>0</kinematic>
      </link>
      <joint name='left_w2' type='revolute'>
        <pose relative_to='left_lower_forearm'>0.115975 0 0 1.5708 -0 1.5708</pose>
        <parent>left_lower_forearm</parent>
        <child>left_wrist</child>
        <axis>
          <xyz>0 0 1</xyz>
          <limit>
            <lower>-3.059</lower>
            <upper>3.059</upper>
            <effort>15</effort>
            <velocity>4</velocity>
          </limit>
          <dynamics>
            <damping>0.7</damping>
            <friction>0</friction>
            <spring_reference>0</spring_reference>
            <spring_stiffness>0</spring_stiffness>
          </dynamics>
        </axis>
        <physics>
          <ode>
            <implicit_spring_damper>1</implicit_spring_damper>
            <cfm_damping>1</cfm_damping>
            <limit>
              <cfm>0</cfm>
              <erp>0.2</erp>
            </limit>
          </ode>
        </physics>
      </joint>
      <link name='left_wrist'>
        <pose relative_to='left_w2'>0 0 0 0 -0 0</pose>
        <inertial>
          <pose>0.003318 0.000616 0.079435 0 -0 0</pose>
          <mass>0.84268</mass>
          <inertia>
            <ixx>0.00285059</ixx>
            <ixy>7.17373e-06</ixy>
            <ixz>2.52032e-05</ixz>
            <iyy>0.00291735</iyy>
            <iyz>2.17353e-05</iyz>
            <izz>0.000560608</izz>
          </inertia>
        </inertial>
        <collision name='left_wrist_collision'>
          <pose>0 0 0 0 -0 0</pose>
          <geometry>
            <cylinder>
              <length>0.165</length>
              <radius>0.06</radius>
            </cylinder>
          </geometry>
          <surface>
            <contact>
              <ode/>
            </contact>
            <bounce/>
            <friction>
              <torsional>
                <ode/>
              </torsional>
              <ode/>
            </friction>
          </surface>
          <max_contacts>10</max_contacts>
        </collision>
        <collision name='left_wrist_fixed_joint_lump__left_hand_collision_1'>
          <pose>0 0 0.09035 0 -0 0</pose>
          <geometry>
            <cylinder>
              <length>0.0464</length>
              <radius>0.04</radius>
            </cylinder>
          </geometry>
          <surface>
            <contact>
              <ode/>
            </contact>
            <bounce/>
            <friction>
              <torsional>
                <ode/>
              </torsional>
              <ode/>
            </friction>
          </surface>
          <max_contacts>10</max_contacts>
        </collision>
        <collision name='left_wrist_fixed_joint_lump__left_gripper_base_collision_2'>
          <pose>0 0 0.13855 1.5708 -0 3.14159</pose>
          <geometry>
            <cylinder>
              <length>0.1</length>
              <radius>0.029</radius>
            </cylinder>
          </geometry>
          <surface>
            <contact>
              <ode/>
            </contact>
            <bounce/>
            <friction>
              <torsional>
                <ode/>
              </torsional>
              <ode/>
            </friction>
          </surface>
          <max_contacts>10</max_contacts>
        </collision>
        <visual name='left_wrist_visual'>
          <pose>0 0 0 0 -0 0</pose>
          <geometry>
            <mesh>
              <scale>1 1 1</scale>
              <uri>/home/gabbiewink/rethink_ws/src/baxter_common/baxter_description/meshes/wrist/W2.DAE</uri>
            </mesh>
          </geometry>
        </visual>
        <visual name='left_wrist_fixed_joint_lump__left_gripper_base_visual_1'>
          <pose>0 0 0.13855 1.5708 -0 3.14159</pose>
          <geometry>
            <mesh>
              <scale>1 1 1</scale>
              <uri>/home/gabbiewink/rethink_ws/src/baxter_common/rethink_ee_description/meshes/electric_gripper/electric_gripper_base.DAE</uri>
            </mesh>
          </geometry>
        </visual>
        <visual name='left_wrist_fixed_joint_lump__left_hand_accelerometer_visual_2'>
          <pose>0.00198 0.000133 0.09895 0 -0 0</pose>
          <geometry>
            <box>
              <size>0.01 0.01 0.01</size>
            </box>
          </geometry>
        </visual>
        <visual name='left_wrist_fixed_joint_lump__left_hand_camera_visual_3'>
          <pose>0.03825 0.012 0.128905 0 0 -1.5708</pose>
          <geometry>
            <cylinder>
              <length>0.01</length>
              <radius>0.02</radius>
            </cylinder>
          </geometry>
        </visual>
        <visual name='left_wrist_fixed_joint_lump__left_hand_range_visual_4'>
          <pose>0.032 -0.020245 0.14235 1.57079 -1.57079 3.14159</pose>
          <geometry>
            <box>
              <size>0.005 0.02 0.005</size>
            </box>
          </geometry>
        </visual>
        <velocity_decay/>
        <sensor name='left_hand_camera' type='camera'>
          <update_rate>30</update_rate>
          <camera name='left_hand_camera'>
            <pose>0 0 0 -1.57079 -1.57079 3.14159</pose>
            <horizontal_fov>1.39626</horizontal_fov>
            <image>
              <width>800</width>
              <height>800</height>
              <format>R8G8B8</format>
            </image>
            <clip>
              <near>0.02</near>
              <far>300</far>
            </clip>
            <noise>
              <type>gaussian</type>
              <mean>0</mean>
              <stddev>0.007</stddev>
            </noise>
          </camera>
          <plugin name='camera_controller' filename='libgazebo_ros_camera.so'>
            <alwaysOn>1</alwaysOn>
            <updateRate>0.0</updateRate>
            <cameraName>left_hand_camera</cameraName>
            <imageTopicName>image</imageTopicName>
            <cameraInfoTopicName>camera_info</cameraInfoTopicName>
            <frameName>left_hand_camera</frameName>
            <hackBaseline>0.07</hackBaseline>
            <distortionK1>0.0</distortionK1>
            <distortionK2>0.0</distortionK2>
            <distortionK3>0.0</distortionK3>
            <distortionT1>0.0</distortionT1>
            <distortionT2>0.0</distortionT2>
            <robotNamespace>/cameras</robotNamespace>
          </plugin>
          <pose>0.03825 0.012 0.128905 0 0 -1.5708</pose>
        </sensor>
        <gravity>0</gravity>
        <velocity_decay/>
        <sensor name='ir_left' type='ray'>
          <ray>
            <scan>
              <horizontal>
                <samples>1</samples>
                <resolution>1</resolution>
                <min_angle>-0.5</min_angle>
                <max_angle>0.5</max_angle>
              </horizontal>
              <vertical>
                <samples>1</samples>
                <min_angle>0</min_angle>
                <max_angle>0</max_angle>
              </vertical>
            </scan>
            <range>
              <min>0.004</min>
              <max>0.4</max>
            </range>
          </ray>
          <plugin name='plugin_4' filename='libgazebo_ros_laser.so'>
            <gaussianNoise>0.005</gaussianNoise>
            <alwaysOn>1</alwaysOn>
            <updateRate>100</updateRate>
            <topicName>/sim/laserscan/left_hand_range/state</topicName>
            <frameName>left_hand_range</frameName>
            <robotNamespace>/</robotNamespace>
          </plugin>
          <always_on>1</always_on>
          <update_rate>100</update_rate>
          <pose>0.032 -0.020245 0.14235 3.14159 -1.57079 1.57079</pose>
        </sensor>
        <self_collide>0</self_collide>
        <enable_wind>0</enable_wind>
        <kinematic>0</kinematic>
      </link>
      <joint name='l_gripper_l_finger_joint' type='prismatic'>
        <pose relative_to='left_wrist'>0 -0.0015 0.15855 0 -0 0</pose>
        <parent>left_wrist</parent>
        <child>l_gripper_l_finger</child>
        <axis>
          <xyz>0 1 0</xyz>
          <limit>
            <lower>0</lower>
            <upper>0.020833</upper>
            <effort>20</effort>
            <velocity>5</velocity>
          </limit>
          <dynamics>
            <damping>0.7</damping>
            <friction>0</friction>
            <spring_reference>0</spring_reference>
            <spring_stiffness>0</spring_stiffness>
          </dynamics>
        </axis>
        <physics>
          <ode>
            <implicit_spring_damper>1</implicit_spring_damper>
            <cfm_damping>1</cfm_damping>
            <limit>
              <cfm>0</cfm>
              <erp>0.2</erp>
            </limit>
          </ode>
        </physics>
      </joint>
      <link name='l_gripper_l_finger'>
        <pose relative_to='l_gripper_l_finger_joint'>0 0 0 0 -0 0</pose>
        <inertial>
          <pose>0 0.00575 0.037567 0 0 -3.14159</pose>
          <mass>0.03</mass>
          <inertia>
            <ixx>0.0200867</ixx>
            <ixy>-2.42939e-22</ixy>
            <ixz>1.5872e-21</ixz>
            <iyy>0.0200847</iyy>
            <iyz>1.29605e-05</iyz>
            <izz>0.020002</izz>
          </inertia>
        </inertial>
        <collision name='l_gripper_l_finger_collision'>
          <pose>0 0.01725 0.0615 0 0 -3.14159</pose>
          <geometry>
            <box>
              <size>0.01 0.0135 0.1127</size>
            </box>
          </geometry>
          <surface>
            <contact>
              <ode>
                <kp>100000</kp>
                <kd>1</kd>
              </ode>
            </contact>
            <friction>
              <ode>
                <mu>1000</mu>
                <mu2>1000</mu2>
                <fdir1>0 0 1</fdir1>
              </ode>
              <torsional>
                <ode/>
              </torsional>
            </friction>
            <bounce/>
          </surface>
          <max_contacts>10</max_contacts>
        </collision>
        <collision name='l_gripper_l_finger_collision_1'>
          <pose>-0.005 -0.003 0.0083 0 0 -3.14159</pose>
          <geometry>
            <box>
              <size>0.01 0.05 0.017</size>
            </box>
          </geometry>
          <surface>
            <contact>
              <ode>
                <kp>100000</kp>
                <kd>1</kd>
              </ode>
            </contact>
            <friction>
              <ode>
                <mu>1000</mu>
                <mu2>1000</mu2>
                <fdir1>0 0 1</fdir1>
              </ode>
              <torsional>
                <ode/>
              </torsional>
            </friction>
            <bounce/>
          </surface>
          <max_contacts>10</max_contacts>
        </collision>
        <collision name='l_gripper_l_finger_tip_collision_2'>
          <pose>0 0.01275 0.0977 0 -0 3.14159</pose>
          <geometry>
            <box>
              <size>0.042 0.0065 0.037</size>
            </box>
          </geometry>
          <surface>
            <contact>
              <ode>
                <kp>100000</kp>
                <kd>1</kd>
              </ode>
            </contact>
            <friction>
              <ode>
                <mu>1000</mu>
                <mu2>1000</mu2>
                <fdir1>0 0 1</fdir1>
              </ode>
              <torsional>
                <ode/>
              </torsional>
            </friction>
            <bounce/>
          </surface>
          <max_contacts>10</max_contacts>
        </collision>
        <visual name='l_gripper_l_finger_visual'>
          <pose>0 0 0 0 0 -3.14159</pose>
          <geometry>
            <mesh>
              <scale>1 1 1</scale>
              <uri>/home/gabbiewink/rethink_ws/src/baxter_common/rethink_ee_description/meshes/electric_gripper/fingers/extended_narrow.DAE</uri>
            </mesh>
          </geometry>
        </visual>
        <visual name='l_gripper_l_finger_tip_visual_1'>
          <pose>0 0.01725 0.1127 0 -0 3.14159</pose>
          <geometry>
            <mesh>
              <scale>1 1 1</scale>
              <uri>/home/gabbiewink/rethink_ws/src/baxter_common/rethink_ee_description/meshes/electric_gripper/fingers/paddle_tip.DAE</uri>
            </mesh>
          </geometry>
        </visual>
        <gravity>1</gravity>
        <velocity_decay/>
        <self_collide>0</self_collide>
        <enable_wind>0</enable_wind>
        <kinematic>0</kinematic>
      </link>
      <joint name='l_gripper_r_finger_joint' type='prismatic'>
        <pose relative_to='left_wrist'>0 0.0015 0.15855 0 -0 0</pose>
        <parent>left_wrist</parent>
        <child>l_gripper_r_finger</child>
        <axis>
          <xyz>0 1 0</xyz>
          <limit>
            <lower>-0.020833</lower>
            <upper>0</upper>
            <effort>20</effort>
            <velocity>5</velocity>
          </limit>
          <dynamics>
            <damping>0.7</damping>
            <friction>0</friction>
            <spring_reference>0</spring_reference>
            <spring_stiffness>0</spring_stiffness>
          </dynamics>
        </axis>
        <physics>
          <ode>
            <implicit_spring_damper>1</implicit_spring_damper>
            <cfm_damping>1</cfm_damping>
            <limit>
              <cfm>0</cfm>
              <erp>0.2</erp>
            </limit>
          </ode>
        </physics>
      </joint>
      <link name='l_gripper_r_finger'>
        <pose relative_to='l_gripper_r_finger_joint'>0 0 0 0 -0 0</pose>
        <inertial>
          <pose>0 -0.00575 0.037567 0 -0 0</pose>
          <mass>0.03</mass>
          <inertia>
            <ixx>0.0200867</ixx>
            <ixy>0</ixy>
            <ixz>0</ixz>
            <iyy>0.0200847</iyy>
            <iyz>1.29605e-05</iyz>
            <izz>0.020002</izz>
          </inertia>
        </inertial>
        <collision name='l_gripper_r_finger_collision'>
          <pose>0 -0.01725 0.0615 0 -0 0</pose>
          <geometry>
            <box>
              <size>0.01 0.0135 0.1127</size>
            </box>
          </geometry>
          <surface>
            <contact>
              <ode>
                <kp>100000</kp>
                <kd>1</kd>
              </ode>
            </contact>
            <friction>
              <ode>
                <mu>1000</mu>
                <mu2>1000</mu2>
                <fdir1>0 0 1</fdir1>
              </ode>
              <torsional>
                <ode/>
              </torsional>
            </friction>
            <bounce/>
          </surface>
          <max_contacts>10</max_contacts>
        </collision>
        <collision name='l_gripper_r_finger_collision_1'>
          <pose>0.005 0.003 0.0083 0 -0 0</pose>
          <geometry>
            <box>
              <size>0.01 0.05 0.017</size>
            </box>
          </geometry>
          <surface>
            <contact>
              <ode>
                <kp>100000</kp>
                <kd>1</kd>
              </ode>
            </contact>
            <friction>
              <ode>
                <mu>1000</mu>
                <mu2>1000</mu2>
                <fdir1>0 0 1</fdir1>
              </ode>
              <torsional>
                <ode/>
              </torsional>
            </friction>
            <bounce/>
          </surface>
          <max_contacts>10</max_contacts>
        </collision>
        <collision name='l_gripper_r_finger_tip_collision_2'>
          <pose>0 -0.01275 0.0977 0 -0 0</pose>
          <geometry>
            <box>
              <size>0.042 0.0065 0.037</size>
            </box>
          </geometry>
          <surface>
            <contact>
              <ode>
                <kp>100000</kp>
                <kd>1</kd>
              </ode>
            </contact>
            <friction>
              <ode>
                <mu>1000</mu>
                <mu2>1000</mu2>
                <fdir1>0 0 1</fdir1>
              </ode>
              <torsional>
                <ode/>
              </torsional>
            </friction>
            <bounce/>
          </surface>
          <max_contacts>10</max_contacts>
        </collision>
        <visual name='l_gripper_r_finger_visual'>
          <pose>0 0 0 0 -0 0</pose>
          <geometry>
            <mesh>
              <scale>1 1 1</scale>
              <uri>/home/gabbiewink/rethink_ws/src/baxter_common/rethink_ee_description/meshes/electric_gripper/fingers/extended_narrow.DAE</uri>
            </mesh>
          </geometry>
        </visual>
        <visual name='l_gripper_r_finger_tip_visual_1'>
          <pose>0 -0.01725 0.1127 0 -0 0</pose>
          <geometry>
            <mesh>
              <scale>1 1 1</scale>
              <uri>/home/gabbiewink/rethink_ws/src/baxter_common/rethink_ee_description/meshes/electric_gripper/fingers/paddle_tip.DAE</uri>
            </mesh>
          </geometry>
        </visual>
        <gravity>1</gravity>
        <velocity_decay/>
        <self_collide>0</self_collide>
        <enable_wind>0</enable_wind>
        <kinematic>0</kinematic>
      </link>
      <joint name='right_s0' type='revolute'>
        <pose relative_to='base'>0.064027 -0.259027 0.129626 0 0 -0.7854</pose>
        <parent>base</parent>
        <child>right_upper_shoulder</child>
        <axis>
          <xyz>0 0 1</xyz>
          <limit>
            <lower>-1.70168</lower>
            <upper>1.70168</upper>
            <effort>50</effort>
            <velocity>1.5</velocity>
          </limit>
          <dynamics>
            <damping>0.7</damping>
            <friction>0</friction>
            <spring_reference>0</spring_reference>
            <spring_stiffness>0</spring_stiffness>
          </dynamics>
        </axis>
        <physics>
          <ode>
            <implicit_spring_damper>1</implicit_spring_damper>
            <cfm_damping>1</cfm_damping>
            <limit>
              <cfm>0</cfm>
              <erp>0.2</erp>
            </limit>
          </ode>
        </physics>
      </joint>
      <link name='right_upper_shoulder'>
        <pose relative_to='right_s0'>0 0 0 0 -0 0</pose>
        <inertial>
          <pose>0.01783 0.00086 0.19127 0 -0 0</pose>
          <mass>5.70044</mass>
          <inertia>
            <ixx>0.047091</ixx>
            <ixy>0.000127876</ixy>
            <ixz>0.0061487</ixz>
            <iyy>0.0376698</iyy>
            <iyz>0.000780869</iyz>
            <izz>0.0359599</izz>
          </inertia>
        </inertial>
        <collision name='right_upper_shoulder_collision'>
          <pose>0 0 0.1361 0 -0 0</pose>
          <geometry>
            <cylinder>
              <length>0.2722</length>
              <radius>0.06</radius>
            </cylinder>
          </geometry>
          <surface>
            <contact>
              <ode/>
            </contact>
            <bounce/>
            <friction>
              <torsional>
                <ode/>
              </torsional>
              <ode/>
            </friction>
          </surface>
          <max_contacts>10</max_contacts>
        </collision>
        <visual name='right_upper_shoulder_visual'>
          <pose>0 0 0 0 -0 0</pose>
          <geometry>
            <mesh>
              <scale>1 1 1</scale>
              <uri>/home/gabbiewink/rethink_ws/src/baxter_common/baxter_description/meshes/upper_shoulder/S0.DAE</uri>
            </mesh>
          </geometry>
        </visual>
        <self_collide>0</self_collide>
        <enable_wind>0</enable_wind>
        <kinematic>0</kinematic>
      </link>
      <joint name='right_s1' type='revolute'>
        <pose relative_to='right_upper_shoulder'>0.069 0 0.27035 -1.5708 0 0</pose>
        <parent>right_upper_shoulder</parent>
        <child>right_lower_shoulder</child>
        <axis>
          <xyz>0 0 1</xyz>
          <limit>
            <lower>-2.147</lower>
            <upper>1.047</upper>
            <effort>50</effort>
            <velocity>1.5</velocity>
          </limit>
          <dynamics>
            <damping>0.7</damping>
            <friction>0</friction>
            <spring_reference>0</spring_reference>
            <spring_stiffness>0</spring_stiffness>
          </dynamics>
        </axis>
        <physics>
          <ode>
            <implicit_spring_damper>1</implicit_spring_damper>
            <cfm_damping>1</cfm_damping>
            <limit>
              <cfm>0</cfm>
              <erp>0.2</erp>
            </limit>
          </ode>
        </physics>
      </joint>
      <link name='right_lower_shoulder'>
        <pose relative_to='right_s1'>0 0 0 0 -0 0</pose>
        <inertial>
          <pose>0.068451 0.00269 -0.00529 0 -0 0</pose>
          <mass>3.22708</mass>
          <inertia>
            <ixx>0.0117521</ixx>
            <ixy>-0.000300954</ixy>
            <ixz>0.00207674</ixz>
            <iyy>0.0278861</iyy>
            <iyz>-0.000188219</iyz>
            <izz>0.0207877</izz>
          </inertia>
        </inertial>
        <collision name='right_lower_shoulder_collision'>
          <pose>0 0 0 0 -0 0</pose>
          <geometry>
            <cylinder>
              <length>0.12</length>
              <radius>0.06</radius>
            </cylinder>
          </geometry>
          <surface>
            <contact>
              <ode/>
            </contact>
            <bounce/>
            <friction>
              <torsional>
                <ode/>
              </torsional>
              <ode/>
            </friction>
          </surface>
          <max_contacts>10</max_contacts>
        </collision>
        <collision name='right_lower_shoulder_fixed_joint_lump__right_upper_elbow_visual_collision_1'>
          <pose>0.2435 -0 0 1.5708 -0 1.5708</pose>
          <geometry>
            <cylinder>
              <length>0.273</length>
              <radius>0.06</radius>
            </cylinder>
          </geometry>
          <surface>
            <contact>
              <ode/>
            </contact>
            <bounce/>
            <friction>
              <torsional>
                <ode/>
              </torsional>
              <ode/>
            </friction>
          </surface>
          <max_contacts>10</max_contacts>
        </collision>
        <visual name='right_lower_shoulder_visual'>
          <pose>0 0 0 0 -0 0</pose>
          <geometry>
            <mesh>
              <scale>1 1 1</scale>
              <uri>/home/gabbiewink/rethink_ws/src/baxter_common/baxter_description/meshes/lower_shoulder/S1.DAE</uri>
            </mesh>
          </geometry>
        </visual>
        <self_collide>0</self_collide>
        <enable_wind>0</enable_wind>
        <kinematic>0</kinematic>
      </link>
      <joint name='right_e0' type='revolute'>
        <pose relative_to='right_lower_shoulder'>0.102 0 0 1.5708 -0 1.5708</pose>
        <parent>right_lower_shoulder</parent>
        <child>right_upper_elbow</child>
        <axis>
          <xyz>0 0 1</xyz>
          <limit>
            <lower>-3.05418</lower>
            <upper>3.05418</upper>
            <effort>50</effort>
            <velocity>1.5</velocity>
          </limit>
          <dynamics>
            <damping>0.7</damping>
            <friction>0</friction>
            <spring_reference>0</spring_reference>
            <spring_stiffness>0</spring_stiffness>
          </dynamics>
        </axis>
        <physics>
          <ode>
            <implicit_spring_damper>1</implicit_spring_damper>
            <cfm_damping>1</cfm_damping>
            <limit>
              <cfm>0</cfm>
              <erp>0.2</erp>
            </limit>
          </ode>
        </physics>
      </joint>
      <link name='right_upper_elbow'>
        <pose relative_to='right_e0'>0 0 0 0 -0 0</pose>
        <inertial>
          <pose>-0.00276 0.00132 0.18086 0 -0 0</pose>
          <mass>4.31272</mass>
          <inertia>
            <ixx>0.0266173</ixx>
            <ixy>0.000292706</ixy>
            <ixz>0.0039219</ixz>
            <iyy>0.0284436</iyy>
            <iyz>0.00108389</iyz>
            <izz>0.0124801</izz>
          </inertia>
        </inertial>
        <collision name='right_upper_elbow_collision'>
          <pose>0 0 -0.0535 0 -0 0</pose>
          <geometry>
            <cylinder>
              <length>0.107</length>
              <radius>0.06</radius>
            </cylinder>
          </geometry>
          <surface>
            <contact>
              <ode/>
            </contact>
            <bounce/>
            <friction>
              <torsional>
                <ode/>
              </torsional>
              <ode/>
            </friction>
          </surface>
          <max_contacts>10</max_contacts>
        </collision>
        <visual name='right_upper_elbow_visual'>
          <pose>0 0 0 0 -0 0</pose>
          <geometry>
            <mesh>
              <scale>1 1 1</scale>
              <uri>/home/gabbiewink/rethink_ws/src/baxter_common/baxter_description/meshes/upper_elbow/E0.DAE</uri>
            </mesh>
          </geometry>
        </visual>
        <self_collide>0</self_collide>
        <enable_wind>0</enable_wind>
        <kinematic>0</kinematic>
      </link>
      <joint name='right_e1' type='revolute'>
        <pose relative_to='right_upper_elbow'>0.069 0 0.26242 1.57079 -1.57079 3.14159</pose>
        <parent>right_upper_elbow</parent>
        <child>right_lower_elbow</child>
        <axis>
          <xyz>0 0 1</xyz>
          <limit>
            <lower>-0.05</lower>
            <upper>2.618</upper>
            <effort>50</effort>
            <velocity>1.5</velocity>
          </limit>
          <dynamics>
            <damping>0.7</damping>
            <friction>0</friction>
            <spring_reference>0</spring_reference>
            <spring_stiffness>0</spring_stiffness>
          </dynamics>
        </axis>
        <physics>
          <ode>
            <implicit_spring_damper>1</implicit_spring_damper>
            <cfm_damping>1</cfm_damping>
            <limit>
              <cfm>0</cfm>
              <erp>0.2</erp>
            </limit>
          </ode>
        </physics>
      </joint>
      <link name='right_lower_elbow'>
        <pose relative_to='right_e1'>0 0 0 0 -0 0</pose>
        <inertial>
          <pose>0.026113 0.00159 -0.011169 0 -0 0</pose>
          <mass>2.07216</mass>
          <inertia>
            <ixx>0.00711585</ixx>
            <ixy>0.000360372</ixy>
            <ixz>0.00074588</ixz>
            <iyy>0.0131827</iyy>
            <iyz>-0.000196632</iyz>
            <izz>0.00926891</izz>
          </inertia>
        </inertial>
        <collision name='right_lower_elbow_collision'>
          <pose>0 0 0 0 -0 0</pose>
          <geometry>
            <cylinder>
              <length>0.1</length>
              <radius>0.06</radius>
            </cylinder>
          </geometry>
          <surface>
            <contact>
              <ode/>
            </contact>
            <bounce/>
            <friction>
              <torsional>
                <ode/>
              </torsional>
              <ode/>
            </friction>
          </surface>
          <max_contacts>10</max_contacts>
        </collision>
        <collision name='right_lower_elbow_fixed_joint_lump__right_upper_forearm_visual_collision_1'>
          <pose>0.224 -0 0 1.5708 -0 1.5708</pose>
          <geometry>
            <cylinder>
              <length>0.272</length>
              <radius>0.06</radius>
            </cylinder>
          </geometry>
          <surface>
            <contact>
              <ode/>
            </contact>
            <bounce/>
            <friction>
              <torsional>
                <ode/>
              </torsional>
              <ode/>
            </friction>
          </surface>
          <max_contacts>10</max_contacts>
        </collision>
        <visual name='right_lower_elbow_visual'>
          <pose>0 0 0 0 -0 0</pose>
          <geometry>
            <mesh>
              <scale>1 1 1</scale>
              <uri>/home/gabbiewink/rethink_ws/src/baxter_common/baxter_description/meshes/lower_elbow/E1.DAE</uri>
            </mesh>
          </geometry>
        </visual>
        <self_collide>0</self_collide>
        <enable_wind>0</enable_wind>
        <kinematic>0</kinematic>
      </link>
      <joint name='right_w0' type='revolute'>
        <pose relative_to='right_lower_elbow'>0.10359 0 0 1.5708 -0 1.5708</pose>
        <parent>right_lower_elbow</parent>
        <child>right_upper_forearm</child>
        <axis>
          <xyz>0 0 1</xyz>
          <limit>
            <lower>-3.059</lower>
            <upper>3.059</upper>
            <effort>15</effort>
            <velocity>4</velocity>
          </limit>
          <dynamics>
            <damping>0.7</damping>
            <friction>0</friction>
            <spring_reference>0</spring_reference>
            <spring_stiffness>0</spring_stiffness>
          </dynamics>
        </axis>
        <physics>
          <ode>
            <implicit_spring_damper>1</implicit_spring_damper>
            <cfm_damping>1</cfm_damping>
            <limit>
              <cfm>0</cfm>
              <erp>0.2</erp>
            </limit>
          </ode>
        </physics>
      </joint>
      <link name='right_upper_forearm'>
        <pose relative_to='right_w0'>0 0 0 0 -0 0</pose>
        <inertial>
          <pose>-0.001682 0.0046 0.139519 0 -0 0</pose>
          <mass>2.24675</mass>
          <inertia>
            <ixx>0.0166775</ixx>
            <ixy>0.000184012</ixy>
            <ixz>0.000186469</ixz>
            <iyy>0.0167549</iyy>
            <iyz>-0.000647332</iyz>
            <izz>0.00374662</izz>
          </inertia>
        </inertial>
        <collision name='right_upper_forearm_collision'>
          <pose>0 0 -0.044 0 -0 0</pose>
          <geometry>
            <cylinder>
              <length>0.088</length>
              <radius>0.06</radius>
            </cylinder>
          </geometry>
          <surface>
            <contact>
              <ode/>
            </contact>
            <bounce/>
            <friction>
              <torsional>
                <ode/>
              </torsional>
              <ode/>
            </friction>
          </surface>
          <max_contacts>10</max_contacts>
        </collision>
        <visual name='right_upper_forearm_visual'>
          <pose>0 0 0 0 -0 0</pose>
          <geometry>
            <mesh>
              <scale>1 1 1</scale>
              <uri>/home/gabbiewink/rethink_ws/src/baxter_common/baxter_description/meshes/upper_forearm/W0.DAE</uri>
            </mesh>
          </geometry>
        </visual>
        <self_collide>0</self_collide>
        <enable_wind>0</enable_wind>
        <kinematic>0</kinematic>
      </link>
      <joint name='right_w1' type='revolute'>
        <pose relative_to='right_upper_forearm'>0.01 0 0.2707 1.57079 -1.57079 3.14159</pose>
        <parent>right_upper_forearm</parent>
        <child>right_lower_forearm</child>
        <axis>
          <xyz>0 0 1</xyz>
          <limit>
            <lower>-1.5708</lower>
            <upper>2.094</upper>
            <effort>15</effort>
            <velocity>4</velocity>
          </limit>
          <dynamics>
            <damping>0.7</damping>
            <friction>0</friction>
            <spring_reference>0</spring_reference>
            <spring_stiffness>0</spring_stiffness>
          </dynamics>
        </axis>
        <physics>
          <ode>
            <implicit_spring_damper>1</implicit_spring_damper>
            <cfm_damping>1</cfm_damping>
            <limit>
              <cfm>0</cfm>
              <erp>0.2</erp>
            </limit>
          </ode>
        </physics>
      </joint>
      <link name='right_lower_forearm'>
        <pose relative_to='right_w1'>0 0 0 0 -0 0</pose>
        <inertial>
          <pose>0.06041 0.00697 0.006 0 -0 0</pose>
          <mass>1.60979</mass>
          <inertia>
            <ixx>0.00387607</ixx>
            <ixy>-0.000443848</ixy>
            <ixz>-0.00021115</ixz>
            <iyy>0.00700538</iyy>
            <iyz>0.000153481</iyz>
            <izz>0.00552755</izz>
          </inertia>
        </inertial>
        <collision name='right_lower_forearm_collision'>
          <pose>0 0 0 0 -0 0</pose>
          <geometry>
            <cylinder>
              <length>0.1</length>
              <radius>0.06</radius>
            </cylinder>
          </geometry>
          <surface>
            <contact>
              <ode/>
            </contact>
            <bounce/>
            <friction>
              <torsional>
                <ode/>
              </torsional>
              <ode/>
            </friction>
          </surface>
          <max_contacts>10</max_contacts>
        </collision>
        <visual name='right_lower_forearm_visual'>
          <pose>0 0 0 0 -0 0</pose>
          <geometry>
            <mesh>
              <scale>1 1 1</scale>
              <uri>/home/gabbiewink/rethink_ws/src/baxter_common/baxter_description/meshes/lower_forearm/W1.DAE</uri>
            </mesh>
          </geometry>
        </visual>
        <self_collide>0</self_collide>
        <enable_wind>0</enable_wind>
        <kinematic>0</kinematic>
      </link>
      <joint name='right_w2' type='revolute'>
        <pose relative_to='right_lower_forearm'>0.115975 0 0 1.5708 -0 1.5708</pose>
        <parent>right_lower_forearm</parent>
        <child>right_wrist</child>
        <axis>
          <xyz>0 0 1</xyz>
          <limit>
            <lower>-3.059</lower>
            <upper>3.059</upper>
            <effort>15</effort>
            <velocity>4</velocity>
          </limit>
          <dynamics>
            <damping>0.7</damping>
            <friction>0</friction>
            <spring_reference>0</spring_reference>
            <spring_stiffness>0</spring_stiffness>
          </dynamics>
        </axis>
        <physics>
          <ode>
            <implicit_spring_damper>1</implicit_spring_damper>
            <cfm_damping>1</cfm_damping>
            <limit>
              <cfm>0</cfm>
              <erp>0.2</erp>
            </limit>
          </ode>
        </physics>
      </joint>
      <link name='right_wrist'>
        <pose relative_to='right_w2'>0 0 0 0 -0 0</pose>
        <inertial>
          <pose>0.003318 0.000616 0.079435 0 -0 0</pose>
          <mass>0.84268</mass>
          <inertia>
            <ixx>0.00285059</ixx>
            <ixy>7.17373e-06</ixy>
            <ixz>2.52032e-05</ixz>
            <iyy>0.00291735</iyy>
            <iyz>2.17353e-05</iyz>
            <izz>0.000560608</izz>
          </inertia>
        </inertial>
        <collision name='right_wrist_collision'>
          <pose>0 0 0 0 -0 0</pose>
          <geometry>
            <cylinder>
              <length>0.165</length>
              <radius>0.06</radius>
            </cylinder>
          </geometry>
          <surface>
            <contact>
              <ode/>
            </contact>
            <bounce/>
            <friction>
              <torsional>
                <ode/>
              </torsional>
              <ode/>
            </friction>
          </surface>
          <max_contacts>10</max_contacts>
        </collision>
        <collision name='right_wrist_fixed_joint_lump__right_hand_collision_1'>
          <pose>0 0 0.09035 0 -0 0</pose>
          <geometry>
            <cylinder>
              <length>0.0464</length>
              <radius>0.04</radius>
            </cylinder>
          </geometry>
          <surface>
            <contact>
              <ode/>
            </contact>
            <bounce/>
            <friction>
              <torsional>
                <ode/>
              </torsional>
              <ode/>
            </friction>
          </surface>
          <max_contacts>10</max_contacts>
        </collision>
        <collision name='right_wrist_fixed_joint_lump__right_gripper_base_collision_2'>
          <pose>0 0 0.13855 1.5708 -0 3.14159</pose>
          <geometry>
            <cylinder>
              <length>0.1</length>
              <radius>0.029</radius>
            </cylinder>
          </geometry>
          <surface>
            <contact>
              <ode/>
            </contact>
            <bounce/>
            <friction>
              <torsional>
                <ode/>
              </torsional>
              <ode/>
            </friction>
          </surface>
          <max_contacts>10</max_contacts>
        </collision>
        <visual name='right_wrist_visual'>
          <pose>0 0 0 0 -0 0</pose>
          <geometry>
            <mesh>
              <scale>1 1 1</scale>
              <uri>/home/gabbiewink/rethink_ws/src/baxter_common/baxter_description/meshes/wrist/W2.DAE</uri>
            </mesh>
          </geometry>
        </visual>
        <visual name='right_wrist_fixed_joint_lump__right_gripper_base_visual_1'>
          <pose>0 0 0.13855 1.5708 -0 3.14159</pose>
          <geometry>
            <mesh>
              <scale>1 1 1</scale>
              <uri>/home/gabbiewink/rethink_ws/src/baxter_common/rethink_ee_description/meshes/electric_gripper/electric_gripper_base.DAE</uri>
            </mesh>
          </geometry>
        </visual>
        <visual name='right_wrist_fixed_joint_lump__right_hand_accelerometer_visual_2'>
          <pose>0.00198 0.000133 0.09895 0 -0 0</pose>
          <geometry>
            <box>
              <size>0.01 0.01 0.01</size>
            </box>
          </geometry>
        </visual>
        <visual name='right_wrist_fixed_joint_lump__right_hand_camera_visual_3'>
          <pose>0.03825 0.012 0.128905 0 0 -1.5708</pose>
          <geometry>
            <cylinder>
              <length>0.01</length>
              <radius>0.02</radius>
            </cylinder>
          </geometry>
        </visual>
        <visual name='right_wrist_fixed_joint_lump__right_hand_range_visual_4'>
          <pose>0.032 -0.020245 0.14235 1.57079 -1.57079 3.14159</pose>
          <geometry>
            <box>
              <size>0.005 0.02 0.005</size>
            </box>
          </geometry>
        </visual>
        <velocity_decay/>
        <sensor name='right_hand_camera' type='camera'>
          <update_rate>30</update_rate>
          <camera name='right_hand_camera'>
            <pose>0 0 0 -1.57079 -1.57079 3.14159</pose>
            <horizontal_fov>1.39626</horizontal_fov>
            <image>
              <width>800</width>
              <height>800</height>
              <format>R8G8B8</format>
            </image>
            <clip>
              <near>0.02</near>
              <far>300</far>
            </clip>
            <noise>
              <type>gaussian</type>
              <mean>0</mean>
              <stddev>0.007</stddev>
            </noise>
          </camera>
          <plugin name='camera_controller' filename='libgazebo_ros_camera.so'>
            <alwaysOn>1</alwaysOn>
            <updateRate>0.0</updateRate>
            <cameraName>right_hand_camera</cameraName>
            <imageTopicName>image</imageTopicName>
            <cameraInfoTopicName>camera_info</cameraInfoTopicName>
            <frameName>right_hand_camera</frameName>
            <hackBaseline>0.07</hackBaseline>
            <distortionK1>0.0</distortionK1>
            <distortionK2>0.0</distortionK2>
            <distortionK3>0.0</distortionK3>
            <distortionT1>0.0</distortionT1>
            <distortionT2>0.0</distortionT2>
            <robotNamespace>/cameras</robotNamespace>
          </plugin>
          <pose>0.03825 0.012 0.128905 0 0 -1.5708</pose>
        </sensor>
        <gravity>0</gravity>
        <velocity_decay/>
        <sensor name='ir_right' type='ray'>
          <ray>
            <scan>
              <horizontal>
                <samples>1</samples>
                <resolution>1</resolution>
                <min_angle>-0.5</min_angle>
                <max_angle>0.5</max_angle>
              </horizontal>
              <vertical>
                <samples>1</samples>
                <min_angle>0</min_angle>
                <max_angle>0</max_angle>
              </vertical>
            </scan>
            <range>
              <min>0.004</min>
              <max>0.4</max>
            </range>
          </ray>
          <plugin name='plugin_3' filename='libgazebo_ros_laser.so'>
            <gaussianNoise>0.005</gaussianNoise>
            <alwaysOn>1</alwaysOn>
            <updateRate>100</updateRate>
            <topicName>/sim/laserscan/right_hand_range/state</topicName>
            <frameName>right_hand_range</frameName>
            <robotNamespace>/</robotNamespace>
          </plugin>
          <always_on>1</always_on>
          <update_rate>100</update_rate>
          <pose>0.032 -0.020245 0.14235 3.14159 -1.57079 1.57079</pose>
        </sensor>
        <self_collide>0</self_collide>
        <enable_wind>0</enable_wind>
        <kinematic>0</kinematic>
      </link>
      <joint name='r_gripper_l_finger_joint' type='prismatic'>
        <pose relative_to='right_wrist'>0 -0.0015 0.15855 0 -0 0</pose>
        <parent>right_wrist</parent>
        <child>r_gripper_l_finger</child>
        <axis>
          <xyz>0 1 0</xyz>
          <limit>
            <lower>0</lower>
            <upper>0.020833</upper>
            <effort>20</effort>
            <velocity>5</velocity>
          </limit>
          <dynamics>
            <damping>0.7</damping>
            <friction>0</friction>
            <spring_reference>0</spring_reference>
            <spring_stiffness>0</spring_stiffness>
          </dynamics>
        </axis>
        <physics>
          <ode>
            <implicit_spring_damper>1</implicit_spring_damper>
            <cfm_damping>1</cfm_damping>
            <limit>
              <cfm>0</cfm>
              <erp>0.2</erp>
            </limit>
          </ode>
        </physics>
      </joint>
      <link name='r_gripper_l_finger'>
        <pose relative_to='r_gripper_l_finger_joint'>0 0 0 0 -0 0</pose>
        <inertial>
          <pose>0 0.00575 0.037567 0 0 -3.14159</pose>
          <mass>0.03</mass>
          <inertia>
            <ixx>0.0200867</ixx>
            <ixy>-2.42939e-22</ixy>
            <ixz>1.5872e-21</ixz>
            <iyy>0.0200847</iyy>
            <iyz>1.29605e-05</iyz>
            <izz>0.020002</izz>
          </inertia>
        </inertial>
        <collision name='r_gripper_l_finger_collision'>
          <pose>0 0.01725 0.0615 0 0 -3.14159</pose>
          <geometry>
            <box>
              <size>0.01 0.0135 0.1127</size>
            </box>
          </geometry>
          <surface>
            <contact>
              <ode>
                <kp>100000</kp>
                <kd>1</kd>
              </ode>
            </contact>
            <friction>
              <ode>
                <mu>1000</mu>
                <mu2>1000</mu2>
                <fdir1>0 0 1</fdir1>
              </ode>
              <torsional>
                <ode/>
              </torsional>
            </friction>
            <bounce/>
          </surface>
          <max_contacts>10</max_contacts>
        </collision>
        <collision name='r_gripper_l_finger_collision_1'>
          <pose>-0.005 -0.003 0.0083 0 0 -3.14159</pose>
          <geometry>
            <box>
              <size>0.01 0.05 0.017</size>
            </box>
          </geometry>
          <surface>
            <contact>
              <ode>
                <kp>100000</kp>
                <kd>1</kd>
              </ode>
            </contact>
            <friction>
              <ode>
                <mu>1000</mu>
                <mu2>1000</mu2>
                <fdir1>0 0 1</fdir1>
              </ode>
              <torsional>
                <ode/>
              </torsional>
            </friction>
            <bounce/>
          </surface>
          <max_contacts>10</max_contacts>
        </collision>
        <collision name='r_gripper_l_finger_tip_collision_2'>
          <pose>0 0.01275 0.0977 0 -0 3.14159</pose>
          <geometry>
            <cylinder>
              <length>0.037</length>
              <radius>0.008</radius>
            </cylinder>
          </geometry>
          <surface>
            <contact>
              <ode>
                <kp>100000</kp>
                <kd>1</kd>
              </ode>
            </contact>
            <friction>
              <ode>
                <mu>1000</mu>
                <mu2>1000</mu2>
                <fdir1>0 0 1</fdir1>
              </ode>
              <torsional>
                <ode/>
              </torsional>
            </friction>
            <bounce/>
          </surface>
          <max_contacts>10</max_contacts>
        </collision>
        <visual name='r_gripper_l_finger_visual'>
          <pose>0 0 0 0 0 -3.14159</pose>
          <geometry>
            <mesh>
              <scale>1 1 1</scale>
              <uri>/home/gabbiewink/rethink_ws/src/baxter_common/rethink_ee_description/meshes/electric_gripper/fingers/extended_narrow.DAE</uri>
            </mesh>
          </geometry>
        </visual>
        <visual name='r_gripper_l_finger_tip_visual_1'>
          <pose>0 0.01725 0.1127 0 -0 3.14159</pose>
          <geometry>
            <mesh>
              <scale>1 1 1</scale>
              <uri>/home/gabbiewink/rethink_ws/src/baxter_common/rethink_ee_description/meshes/electric_gripper/fingers/half_round_tip.DAE</uri>
            </mesh>
          </geometry>
        </visual>
        <gravity>1</gravity>
        <velocity_decay/>
        <self_collide>0</self_collide>
        <enable_wind>0</enable_wind>
        <kinematic>0</kinematic>
      </link>
      <joint name='r_gripper_r_finger_joint' type='prismatic'>
        <pose relative_to='right_wrist'>0 0.0015 0.15855 0 -0 0</pose>
        <parent>right_wrist</parent>
        <child>r_gripper_r_finger</child>
        <axis>
          <xyz>0 1 0</xyz>
          <limit>
            <lower>-0.020833</lower>
            <upper>0</upper>
            <effort>20</effort>
            <velocity>5</velocity>
          </limit>
          <dynamics>
            <damping>0.7</damping>
            <friction>0</friction>
            <spring_reference>0</spring_reference>
            <spring_stiffness>0</spring_stiffness>
          </dynamics>
        </axis>
        <physics>
          <ode>
            <implicit_spring_damper>1</implicit_spring_damper>
            <cfm_damping>1</cfm_damping>
            <limit>
              <cfm>0</cfm>
              <erp>0.2</erp>
            </limit>
          </ode>
        </physics>
      </joint>
      <link name='r_gripper_r_finger'>
        <pose relative_to='r_gripper_r_finger_joint'>0 0 0 0 -0 0</pose>
        <inertial>
          <pose>0 -0.00575 0.037567 0 -0 0</pose>
          <mass>0.03</mass>
          <inertia>
            <ixx>0.0200867</ixx>
            <ixy>0</ixy>
            <ixz>0</ixz>
            <iyy>0.0200847</iyy>
            <iyz>1.29605e-05</iyz>
            <izz>0.020002</izz>
          </inertia>
        </inertial>
        <collision name='r_gripper_r_finger_collision'>
          <pose>0 -0.01725 0.0615 0 -0 0</pose>
          <geometry>
            <box>
              <size>0.01 0.0135 0.1127</size>
            </box>
          </geometry>
          <surface>
            <contact>
              <ode>
                <kp>100000</kp>
                <kd>1</kd>
              </ode>
            </contact>
            <friction>
              <ode>
                <mu>1000</mu>
                <mu2>1000</mu2>
                <fdir1>0 0 1</fdir1>
              </ode>
              <torsional>
                <ode/>
              </torsional>
            </friction>
            <bounce/>
          </surface>
          <max_contacts>10</max_contacts>
        </collision>
        <collision name='r_gripper_r_finger_collision_1'>
          <pose>0.005 0.003 0.0083 0 -0 0</pose>
          <geometry>
            <box>
              <size>0.01 0.05 0.017</size>
            </box>
          </geometry>
          <surface>
            <contact>
              <ode>
                <kp>100000</kp>
                <kd>1</kd>
              </ode>
            </contact>
            <friction>
              <ode>
                <mu>1000</mu>
                <mu2>1000</mu2>
                <fdir1>0 0 1</fdir1>
              </ode>
              <torsional>
                <ode/>
              </torsional>
            </friction>
            <bounce/>
          </surface>
          <max_contacts>10</max_contacts>
        </collision>
        <collision name='r_gripper_r_finger_tip_collision_2'>
          <pose>0 -0.01275 0.0977 0 -0 0</pose>
          <geometry>
            <cylinder>
              <length>0.037</length>
              <radius>0.008</radius>
            </cylinder>
          </geometry>
          <surface>
            <contact>
              <ode>
                <kp>100000</kp>
                <kd>1</kd>
              </ode>
            </contact>
            <friction>
              <ode>
                <mu>1000</mu>
                <mu2>1000</mu2>
                <fdir1>0 0 1</fdir1>
              </ode>
              <torsional>
                <ode/>
              </torsional>
            </friction>
            <bounce/>
          </surface>
          <max_contacts>10</max_contacts>
        </collision>
        <visual name='r_gripper_r_finger_visual'>
          <pose>0 0 0 0 -0 0</pose>
          <geometry>
            <mesh>
              <scale>1 1 1</scale>
              <uri>/home/gabbiewink/rethink_ws/src/baxter_common/rethink_ee_description/meshes/electric_gripper/fingers/extended_narrow.DAE</uri>
            </mesh>
          </geometry>
        </visual>
        <visual name='r_gripper_r_finger_tip_visual_1'>
          <pose>0 -0.01725 0.1127 0 -0 0</pose>
          <geometry>
            <mesh>
              <scale>1 1 1</scale>
              <uri>/home/gabbiewink/rethink_ws/src/baxter_common/rethink_ee_description/meshes/electric_gripper/fingers/half_round_tip.DAE</uri>
            </mesh>
          </geometry>
        </visual>
        <gravity>1</gravity>
        <velocity_decay/>
        <self_collide>0</self_collide>
        <enable_wind>0</enable_wind>
        <kinematic>0</kinematic>
      </link>
      <static>0</static>
      <plugin name='baxter_ros_control' filename='libbaxter_gazebo_ros_control.so'>
        <robotNamespace>/robot</robotNamespace>
      </plugin>
      <pose>0 0 0.93 0 -0 0</pose>
    </model>
    <model name='table'>
      <static>1</static>
      <link name='link'>
        <collision name='surface'>
          <pose>0 0 1 0 -0 0</pose>
          <geometry>
            <box>
              <size>1.5 0.8 0.03</size>
            </box>
          </geometry>
          <surface>
            <friction>
              <ode>
                <mu>0.6</mu>
                <mu2>0.6</mu2>
              </ode>
              <torsional>
                <ode/>
              </torsional>
            </friction>
            <contact>
              <ode/>
            </contact>
            <bounce/>
          </surface>
          <max_contacts>10</max_contacts>
        </collision>
        <visual name='visual1'>
          <pose>0 0 1 0 -0 0</pose>
          <geometry>
            <box>
              <size>1.5 0.8 0.03</size>
            </box>
          </geometry>
          <material>
            <script>
              <uri>file://media/materials/scripts/gazebo.material</uri>
              <name>Gazebo/Wood</name>
            </script>
          </material>
        </visual>
        <collision name='front_left_leg'>
          <pose>0.68 0.38 0.5 0 -0 0</pose>
          <geometry>
            <cylinder>
              <radius>0.02</radius>
              <length>1</length>
            </cylinder>
          </geometry>
          <surface>
            <contact>
              <ode/>
            </contact>
            <bounce/>
            <friction>
              <torsional>
                <ode/>
              </torsional>
              <ode/>
            </friction>
          </surface>
          <max_contacts>10</max_contacts>
        </collision>
        <visual name='front_left_leg'>
          <pose>0.68 0.38 0.5 0 -0 0</pose>
          <geometry>
            <cylinder>
              <radius>0.02</radius>
              <length>1</length>
            </cylinder>
          </geometry>
          <material>
            <script>
              <uri>file://media/materials/scripts/gazebo.material</uri>
              <name>Gazebo/Grey</name>
            </script>
          </material>
        </visual>
        <collision name='front_right_leg'>
          <pose>0.68 -0.38 0.5 0 -0 0</pose>
          <geometry>
            <cylinder>
              <radius>0.02</radius>
              <length>1</length>
            </cylinder>
          </geometry>
          <surface>
            <contact>
              <ode/>
            </contact>
            <bounce/>
            <friction>
              <torsional>
                <ode/>
              </torsional>
              <ode/>
            </friction>
          </surface>
          <max_contacts>10</max_contacts>
        </collision>
        <visual name='front_right_leg'>
          <pose>0.68 -0.38 0.5 0 -0 0</pose>
          <geometry>
            <cylinder>
              <radius>0.02</radius>
              <length>1</length>
            </cylinder>
          </geometry>
          <material>
            <script>
              <uri>file://media/materials/scripts/gazebo.material</uri>
              <name>Gazebo/Grey</name>
            </script>
          </material>
        </visual>
        <collision name='back_right_leg'>
          <pose>-0.68 -0.38 0.5 0 -0 0</pose>
          <geometry>
            <cylinder>
              <radius>0.02</radius>
              <length>1</length>
            </cylinder>
          </geometry>
          <surface>
            <contact>
              <ode/>
            </contact>
            <bounce/>
            <friction>
              <torsional>
                <ode/>
              </torsional>
              <ode/>
            </friction>
          </surface>
          <max_contacts>10</max_contacts>
        </collision>
        <visual name='back_right_leg'>
          <pose>-0.68 -0.38 0.5 0 -0 0</pose>
          <geometry>
            <cylinder>
              <radius>0.02</radius>
              <length>1</length>
            </cylinder>
          </geometry>
          <material>
            <script>
              <uri>file://media/materials/scripts/gazebo.material</uri>
              <name>Gazebo/Grey</name>
            </script>
          </material>
        </visual>
        <collision name='back_left_leg'>
          <pose>-0.68 0.38 0.5 0 -0 0</pose>
          <geometry>
            <cylinder>
              <radius>0.02</radius>
              <length>1</length>
            </cylinder>
          </geometry>
          <surface>
            <contact>
              <ode/>
            </contact>
            <bounce/>
            <friction>
              <torsional>
                <ode/>
              </torsional>
              <ode/>
            </friction>
          </surface>
          <max_contacts>10</max_contacts>
        </collision>
        <visual name='back_left_leg'>
          <pose>-0.68 0.38 0.5 0 -0 0</pose>
          <geometry>
            <cylinder>
              <radius>0.02</radius>
              <length>1</length>
            </cylinder>
          </geometry>
          <material>
            <script>
              <uri>file://media/materials/scripts/gazebo.material</uri>
              <name>Gazebo/Grey</name>
            </script>
          </material>
        </visual>
        <self_collide>0</self_collide>
        <enable_wind>0</enable_wind>
        <kinematic>0</kinematic>
      </link>
      <pose>2.71398 -0.125953 0 0 -0 0</pose>
    </model>
    <state world_name='default'>
      <sim_time>131 989000000</sim_time>
      <real_time>76 619223615</real_time>
      <wall_time>1604721694 156954667</wall_time>
      <iterations>70998</iterations>
      <model name='baxter'>
        <pose>0 -0 0.93 0 -0 0</pose>
        <scale>1 1 1</scale>
        <link name='base'>
          <pose>0 -0 0.93 0 -0 0</pose>
          <velocity>-0 0 0 0 -0 0</velocity>
          <acceleration>-0 0 -0 0 -0 0</acceleration>
          <wrench>-3e-06 9e-06 -5e-06 0 -0 0</wrench>
        </link>
        <link name='head'>
          <pose>0.06 -0 1.616 0 0 -8.7e-05</pose>
          <velocity>-0 -0 -0 0 -0 -2e-06</velocity>
          <acceleration>-0 -0 0 -0 -0 -0</acceleration>
          <wrench>-0 -0 0 0 -0 0</wrench>
        </link>
        <link name='l_gripper_l_finger'>
          <pose>0.161872 0.418742 0.330739 -3.12677 0.00092 -1.68476</pose>
          <velocity>0 -0 0 -1e-06 -0 1.1e-05</velocity>
          <acceleration>-0 0 1e-06 0 1e-06 0</acceleration>
          <wrench>-0 0 0 0 -0 0</wrench>
        </link>
        <link name='l_gripper_r_finger'>
          <pose>0.179588 0.416714 0.331003 -3.12677 0.00092 -1.68476</pose>
          <velocity>0 -0 -0 -1e-06 -0 1.1e-05</velocity>
          <acceleration>-0 0 1e-06 0 -0 0</acceleration>
          <wrench>-0 0 0 0 -0 0</wrench>
        </link>
        <link name='left_lower_elbow'>
          <pose>0.171537 0.417528 0.979903 -1.64328 1.53998 0.907802</pose>
          <velocity>1e-06 -0 0 1e-06 -0 -6e-06</velocity>
          <acceleration>-0 -0 1e-06 1e-06 -0 4e-06</acceleration>
          <wrench>-0 -1e-06 2e-06 0 -0 0</wrench>
        </link>
        <link name='left_lower_forearm'>
          <pose>0.177008 0.416754 0.60552 -3.02925 1.55595 -0.051702</pose>
          <velocity>1e-06 0 -0 -1e-06 -0 3e-06</velocity>
          <acceleration>-0 0 1e-06 0 -0 1e-06</acceleration>
          <wrench>-0 0 1e-06 0 -0 0</wrench>
        </link>
        <link name='left_lower_shoulder'>
          <pose>0.102668 0.316193 1.32998 -1.5708 1.047 0.976392</pose>
          <velocity>0 -0 0 0 -0 -4e-06</velocity>
          <acceleration>-0 -1e-06 0 1e-06 -2e-06 1e-06</acceleration>
          <wrench>-1e-06 -2e-06 2e-06 0 -0 0</wrench>
        </link>
        <link name='left_upper_elbow'>
          <pose>0.131238 0.35846 1.24165 -3.13902 0.523787 -2.16007</pose>
          <velocity>0 -0 0 1e-06 1e-06 -6e-06</velocity>
          <acceleration>-0 -0 1e-06 1e-06 -2e-06 2e-06</acceleration>
          <wrench>-1e-06 -2e-06 3e-06 0 -0 0</wrench>
        </link>
        <link name='left_upper_forearm'>
          <pose>0.173502 0.420044 0.876362 -3.12683 0.027053 -1.73446</pose>
          <velocity>1e-06 -0 0 1e-06 0 3e-06</velocity>
          <acceleration>-0 -0 1e-06 1e-06 -0 1e-06</acceleration>
          <wrench>-0 -0 2e-06 0 -0 0</wrench>
        </link>
        <link name='left_upper_shoulder'>
          <pose>0.064027 0.259027 1.05963 0 -0 0.976398</pose>
          <velocity>0 -0 0 0 -0 -4e-06</velocity>
          <acceleration>-0 -1e-06 0 1e-06 -1e-06 1e-06</acceleration>
          <wrench>-1e-06 -6e-06 2e-06 0 -0 0</wrench>
        </link>
        <link name='left_wrist'>
          <pose>0.178727 0.416665 0.489558 -3.12677 0.00092 -1.68476</pose>
          <velocity>0 0 -0 -1e-06 -0 1.1e-05</velocity>
          <acceleration>-0 0 1e-06 0 1e-06 0</acceleration>
          <wrench>-0 0 1e-06 0 -0 0</wrench>
        </link>
        <link name='r_gripper_l_finger'>
          <pose>0.184602 -0.423162 0.332004 -3.12769 0.096162 2.74989</pose>
          <velocity>7e-06 0.000164 -3e-06 -0.000117 6e-05 0.004538</velocity>
          <acceleration>0.051976 0.125393 -0.001894 -0.004464 0.001774 -0.001276</acceleration>
          <wrench>0.001559 0.003762 -5.7e-05 0 -0 0</wrench>
        </link>
        <link name='r_gripper_r_finger'>
          <pose>0.177773 -0.439634 0.332251 -3.12769 0.096162 2.74989</pose>
          <velocity>3e-05 8e-06 1e-06 -0.000118 6e-05 0.004539</velocity>
          <acceleration>-0.060668 -0.146182 0.002302 -0.003477 0.001624 0.00042</acceleration>
          <wrench>-0.00182 -0.004385 6.9e-05 0 -0 0</wrench>
        </link>
        <link name='right_lower_elbow'>
          <pose>0.158159 -0.425821 0.979903 -1.36139 1.54978 -0.858351</pose>
          <velocity>3e-06 2e-06 0 -1e-06 -4.9e-05 -8.5e-05</velocity>
          <acceleration>9.6e-05 -0.000106 7.8e-05 0.000662 0.000162 -0.001171</acceleration>
          <wrench>0.0002 -0.00022 0.000162 0 -0 0</wrench>
        </link>
        <link name='right_lower_forearm'>
          <pose>0.154295 -0.427431 0.605502 -1.65706 1.47363 -0.535447</pose>
          <velocity>5e-06 -3.3e-05 0 -4.9e-05 2e-05 0.00373</velocity>
          <acceleration>6.2e-05 0.0003 9.3e-05 0.000427 -0.000454 0.005674</acceleration>
          <wrench>0.0001 0.000482 0.00015 0 -0 0</wrench>
        </link>
        <link name='right_lower_shoulder'>
          <pose>0.097751 -0.319224 1.32998 -1.5708 1.047 -1.06014</pose>
          <velocity>-1e-06 -0 0 0 -0 -1.2e-05</velocity>
          <acceleration>-1.3e-05 -3.2e-05 2e-05 -3.5e-05 -2.6e-05 -0.000217</acceleration>
          <wrench>-4.2e-05 -0.000104 6.4e-05 0 -0 0</wrench>
        </link>
        <link name='right_upper_elbow'>
          <pose>0.122685 -0.363733 1.24165 3.13654 0.523764 2.07134</pose>
          <velocity>-1e-06 -1e-06 0 2e-05 -3.7e-05 -8.5e-05</velocity>
          <acceleration>1.7e-05 -0.000135 9e-05 2.7e-05 -0.001227 -0.001201</acceleration>
          <wrench>7.2e-05 -0.000582 0.000387 0 -0 0</wrench>
        </link>
        <link name='right_upper_forearm'>
          <pose>0.159583 -0.427469 0.876335 -3.13323 0.019282 2.69216</pose>
          <velocity>8e-06 1e-06 0 -5.4e-05 1.1e-05 0.00373</velocity>
          <acceleration>7.7e-05 0.000137 8.5e-05 0.000977 -8.2e-05 0.003813</acceleration>
          <wrench>0.000173 0.000308 0.000192 0 -0 0</wrench>
        </link>
        <link name='right_upper_shoulder'>
          <pose>0.064028 -0.259028 1.05963 0 -2e-06 -1.06014</pose>
          <velocity>-0 -0 0 0 0 -1.2e-05</velocity>
          <acceleration>-2e-05 1.8e-05 1e-06 5e-06 -1e-05 -0.000242</acceleration>
          <wrench>-0.000114 0.000104 4e-06 0 -0 0</wrench>
        </link>
        <link name='right_wrist'>
          <pose>0.163971 -0.433171 0.490074 -3.12769 0.096162 2.74989</pose>
          <velocity>2.4e-05 -2e-06 0 -0.000116 5.9e-05 0.004539</velocity>
          <acceleration>0.000149 0.000461 8.6e-05 0.001275 -0.000469 -0.000136</acceleration>
          <wrench>0.000126 0.000389 7.3e-05 0 -0 0</wrench>
        </link>
      </model>
      <model name='ground_plane'>
        <pose>0 0 0 0 -0 0</pose>
        <scale>1 1 1</scale>
        <link name='link'>
          <pose>0 0 0 0 -0 0</pose>
          <velocity>0 0 0 0 -0 0</velocity>
          <acceleration>0 0 0 0 -0 0</acceleration>
          <wrench>0 0 0 0 -0 0</wrench>
        </link>
      </model>
      <model name='table'>
        <pose>1.44582 -0.146892 -0 0 0 -1.55429</pose>
        <scale>1 1 1</scale>
        <link name='link'>
          <pose>1.44582 -0.146892 -0 0 0 -1.55429</pose>
          <velocity>0 0 0 0 -0 0</velocity>
          <acceleration>0 0 0 0 -0 0</acceleration>
          <wrench>0 0 0 0 -0 0</wrench>
        </link>
      </model>
      <light name='sun'>
        <pose>0 0 10 0 -0 0</pose>
      </light>
    </state>
  </world>
</sdf>
